<robot name = "robot">
    <link name="Torso">
        <inertial>
            <origin xyz="0 0 1" rpy="0 0 0"/>
            <mass value="1" />
            <inertia ixx="100" ixy="0" ixz="0" iyy="100" iyz="0" izz="100" />
        </inertial>
        <visual>
            <origin xyz="0 0 1" rpy="0 0 0"/>
            <geometry>
                <box size="2 0.5 0.5" />
            </geometry>
            <material name="Cyan">
                <color rgba="0 1.0 1.0 1.0"/>
            </material>
        </visual>
        <collision>
            <origin xyz="0 0 1" rpy="0 0 0"/>
            <geometry>
                <box size="2 0.5 0.5" />
            </geometry>
        </collision>
    </link>
    <joint name="Torso_Head" type="revolute">
       <parent link="Torso"/>
       <child  link="Head"/>
       <origin rpy="0 0 0" xyz="1 0 1.25" />
     <axis xyz="0 1 0"/>
       <limit effort="0.0" lower="-3.14159" upper="3.14159" velocity="0.0"/>
    </joint>
    <link name="Head">
        <inertial>
            <origin xyz="0.25 0 0.25" rpy="0 0 0"/>
            <mass value="1" />
            <inertia ixx="100" ixy="0" ixz="0" iyy="100" iyz="0" izz="100" />
        </inertial>
        <visual>
            <origin xyz="0.25 0 0.25" rpy="0 0 0"/>
            <geometry>
                <box size="0.5 0.5 0.5" />
            </geometry>
            <material name="Cyan">
                <color rgba="0 1.0 1.0 1.0"/>
            </material>
        </visual>
        <collision>
            <origin xyz="0.25 0 0.25" rpy="0 0 0"/>
            <geometry>
                <box size="0.5 0.5 0.5" />
            </geometry>
        </collision>
    </link>
    <joint name="Torso_FrontRight" type="revolute">
       <parent link="Torso"/>
       <child  link="FrontRight"/>
       <origin rpy="0 0 0" xyz="1 -0.25 0.75" />
     <axis xyz="0 1 0"/>
       <limit effort="0.0" lower="-3.14159" upper="3.14159" velocity="0.0"/>
    </joint>
    <link name="FrontRight">
        <inertial>
            <origin xyz="0 0 -0.375" rpy="0 0 0"/>
            <mass value="1" />
            <inertia ixx="100" ixy="0" ixz="0" iyy="100" iyz="0" izz="100" />
        </inertial>
        <visual>
            <origin xyz="0 0 -0.375" rpy="0 0 0"/>
            <geometry>
                <box size="0.125 0.125 0.75" />
            </geometry>
            <material name="Cyan">
                <color rgba="0 1.0 1.0 1.0"/>
            </material>
        </visual>
        <collision>
            <origin xyz="0 0 -0.375" rpy="0 0 0"/>
            <geometry>
                <box size="0.125 0.125 0.75" />
            </geometry>
        </collision>
    </link>
    <joint name="FrontRight_FrontLowerRight" type="revolute">
       <parent link="FrontRight"/>
       <child  link="FrontLowerRight"/>
       <origin rpy="0 0 0" xyz="0 0 -0.75" />
     <axis xyz="0 1 0"/>
       <limit effort="0.0" lower="-3.14159" upper="3.14159" velocity="0.0"/>
    </joint>
    <link name="FrontLowerRight">
        <inertial>
            <origin xyz="0 0 -0.125" rpy="0 0 0"/>
            <mass value="1" />
            <inertia ixx="100" ixy="0" ixz="0" iyy="100" iyz="0" izz="100" />
        </inertial>
        <visual>
            <origin xyz="0 0 -0.125" rpy="0 0 0"/>
            <geometry>
                <box size="0.25 0.25 0.25" />
            </geometry>
            <material name="Cyan">
                <color rgba="0 1.0 1.0 1.0"/>
            </material>
        </visual>
        <collision>
            <origin xyz="0 0 -0.125" rpy="0 0 0"/>
            <geometry>
                <box size="0.25 0.25 0.25" />
            </geometry>
        </collision>
    </link>
    <joint name="Torso_BackRight" type="revolute">
       <parent link="Torso"/>
       <child  link="BackRight"/>
       <origin rpy="0 0 0" xyz="-1 -0.25 0.75" />
     <axis xyz="0 1 0"/>
       <limit effort="0.0" lower="-3.14159" upper="3.14159" velocity="0.0"/>
    </joint>
    <link name="BackRight">
        <inertial>
            <origin xyz="0 0 -0.25" rpy="0 0 0"/>
            <mass value="1" />
            <inertia ixx="100" ixy="0" ixz="0" iyy="100" iyz="0" izz="100" />
        </inertial>
        <visual>
            <origin xyz="0 0 -0.25" rpy="0 0 0"/>
            <geometry>
                <box size="0.125 0.125 0.5" />
            </geometry>
            <material name="Cyan">
                <color rgba="0 1.0 1.0 1.0"/>
            </material>
        </visual>
        <collision>
            <origin xyz="0 0 -0.25" rpy="0 0 0"/>
            <geometry>
                <box size="0.125 0.125 0.5" />
            </geometry>
        </collision>
    </link>
    <joint name="BackRight_BackLowerRight" type="revolute">
       <parent link="BackRight"/>
       <child  link="BackLowerRight"/>
       <origin rpy="0 0 0" xyz="0 0 -0.5" />
     <axis xyz="0 1 0"/>
       <limit effort="0.0" lower="-3.14159" upper="3.14159" velocity="0.0"/>
    </joint>
    <link name="BackLowerRight">
        <inertial>
            <origin xyz="0 0 -0.25" rpy="0 0 0"/>
            <mass value="1" />
            <inertia ixx="100" ixy="0" ixz="0" iyy="100" iyz="0" izz="100" />
        </inertial>
        <visual>
            <origin xyz="0 0 -0.25" rpy="0 0 0"/>
            <geometry>
                <box size="0.125 0.125 0.5" />
            </geometry>
            <material name="Cyan">
                <color rgba="0 1.0 1.0 1.0"/>
            </material>
        </visual>
        <collision>
            <origin xyz="0 0 -0.25" rpy="0 0 0"/>
            <geometry>
                <box size="0.125 0.125 0.5" />
            </geometry>
        </collision>
    </link>
    <joint name="Torso_FrontLeft" type="revolute">
       <parent link="Torso"/>
       <child  link="FrontLeft"/>
       <origin rpy="0 0 0" xyz="1 0.25 0.75" />
     <axis xyz="0 1 0"/>
       <limit effort="0.0" lower="-3.14159" upper="3.14159" velocity="0.0"/>
    </joint>
    <link name="FrontLeft">
        <inertial>
            <origin xyz="0 0 -0.375" rpy="0 0 0"/>
            <mass value="1" />
            <inertia ixx="100" ixy="0" ixz="0" iyy="100" iyz="0" izz="100" />
        </inertial>
        <visual>
            <origin xyz="0 0 -0.375" rpy="0 0 0"/>
            <geometry>
                <box size="0.125 0.125 0.75" />
            </geometry>
            <material name="Cyan">
                <color rgba="0 1.0 1.0 1.0"/>
            </material>
        </visual>
        <collision>
            <origin xyz="0 0 -0.375" rpy="0 0 0"/>
            <geometry>
                <box size="0.125 0.125 0.75" />
            </geometry>
        </collision>
    </link>
    <joint name="FrontLeft_FrontLowerLeft" type="revolute">
       <parent link="FrontLeft"/>
       <child  link="FrontLowerLeft"/>
       <origin rpy="0 0 0" xyz="0 0 -0.75" />
     <axis xyz="0 1 0"/>
       <limit effort="0.0" lower="-3.14159" upper="3.14159" velocity="0.0"/>
    </joint>
    <link name="FrontLowerLeft">
        <inertial>
            <origin xyz="0 0 -0.125" rpy="0 0 0"/>
            <mass value="1" />
            <inertia ixx="100" ixy="0" ixz="0" iyy="100" iyz="0" izz="100" />
        </inertial>
        <visual>
            <origin xyz="0 0 -0.125" rpy="0 0 0"/>
            <geometry>
                <box size="0.25 0.25 0.25" />
            </geometry>
            <material name="Cyan">
                <color rgba="0 1.0 1.0 1.0"/>
            </material>
        </visual>
        <collision>
            <origin xyz="0 0 -0.125" rpy="0 0 0"/>
            <geometry>
                <box size="0.25 0.25 0.25" />
            </geometry>
        </collision>
    </link>
    <joint name="Torso_BackLeft" type="revolute">
       <parent link="Torso"/>
       <child  link="BackLeft"/>
       <origin rpy="0 0 0" xyz="-1 0.25 0.75" />
     <axis xyz="0 1 0"/>
       <limit effort="0.0" lower="-3.14159" upper="3.14159" velocity="0.0"/>
    </joint>
    <link name="BackLeft">
        <inertial>
            <origin xyz="0 0 -0.25" rpy="0 0 0"/>
            <mass value="1" />
            <inertia ixx="100" ixy="0" ixz="0" iyy="100" iyz="0" izz="100" />
        </inertial>
        <visual>
            <origin xyz="0 0 -0.25" rpy="0 0 0"/>
            <geometry>
                <box size="0.125 0.125 0.5" />
            </geometry>
            <material name="Cyan">
                <color rgba="0 1.0 1.0 1.0"/>
            </material>
        </visual>
        <collision>
            <origin xyz="0 0 -0.25" rpy="0 0 0"/>
            <geometry>
                <box size="0.125 0.125 0.5" />
            </geometry>
        </collision>
    </link>
    <joint name="BackLeft_BackLowerLeft" type="revolute">
       <parent link="BackLeft"/>
       <child  link="BackLowerLeft"/>
       <origin rpy="0 0 0" xyz="0 0 -0.5" />
     <axis xyz="0 1 0"/>
       <limit effort="0.0" lower="-3.14159" upper="3.14159" velocity="0.0"/>
    </joint>
    <link name="BackLowerLeft">
        <inertial>
            <origin xyz="0 0 -0.25" rpy="0 0 0"/>
            <mass value="1" />
            <inertia ixx="100" ixy="0" ixz="0" iyy="100" iyz="0" izz="100" />
        </inertial>
        <visual>
            <origin xyz="0 0 -0.25" rpy="0 0 0"/>
            <geometry>
                <box size="0.125 0.125 0.5" />
            </geometry>
            <material name="Cyan">
                <color rgba="0 1.0 1.0 1.0"/>
            </material>
        </visual>
        <collision>
            <origin xyz="0 0 -0.25" rpy="0 0 0"/>
            <geometry>
                <box size="0.125 0.125 0.5" />
            </geometry>
        </collision>
    </link>
</robot>